`try-catch` 是一种 JavaScript 的错误处理机制，可以捕获和处理在代码运行时发生的错误。使用 `try-catch` 可以使程序更加健壮，防止错误导致程序崩溃。

`try-catch` 语句由 `try` 块和一个或多个 `catch` 块组成。`try` 块中的代码表示尝试运行的代码，如果代码运行正常，则继续执行 `try` 块中的代码。如果 `try` 块中的代码发生错误，则控制流程会立即跳转到 `catch` 块，执行 `catch` 块中的代码。`catch` 块用于捕获错误，并对错误进行处理。在 `catch` 块中，可以使用 `console.log()` 方法打印错误信息或者采取其他适当的错误处理方法。

以下是 `try-catch` 的基本语法：

```js
try {
    // 尝试运行的代码
} catch(error) {
    // 错误处理代码
}
```

在 `try` 块中，可以放置任何可能会抛出错误的代码。例如，可以在 `try` 块中调用一个可能会返回错误的函数，或者使用一个可能会抛出异常的表达式。如果在 `try` 块中发生错误，控制流程将立即跳转到 `catch` 块中，错误对象将传递给 `catch` 块中的 `error` 参数。

在 `catch` 块中，可以访问 `error` 对象，并对其进行处理。例如，可以打印错误信息，或者使用其他适当的错误处理方法。需要注意的是，当程序执行完 `catch` 块中的代码后，控制流程将继续执行 `try-catch` 语句后面的代码。

以下是一个使用 `try-catch` 处理错误的示例：

```js
try {
    const result = divide(10, 0);
    console.log(result);
} catch(error) {
    console.log('发生了一个错误：' + error.message);
}

function divide(a, b) {
    if (b === 0) {
        throw new Error('除数不能为零');
    }
    return a / b;
}
```

在上面的示例中，`try` 块中调用了 `divide()` 函数，该函数可能会抛出一个错误。如果 `divide()` 函数抛出了一个错误，控制流程将立即跳转到 `catch` 块中，打印错误信息。否则，控制流程将继续执行 `try` 块中的代码，打印结果。